Failure # 1 (occurred at 2023-06-02_14-52-22)
[36mray::ImplicitFunc.train()[39m (pid=6231, ip=172.17.0.3, repr=train)
  File "/home/vscode/.cache/pypoetry/virtualenvs/deep-learning-G3c9zDRR-py3.9/lib/python3.9/site-packages/ray/tune/trainable/trainable.py", line 384, in train
    raise skipped from exception_cause(skipped)
  File "/home/vscode/.cache/pypoetry/virtualenvs/deep-learning-G3c9zDRR-py3.9/lib/python3.9/site-packages/ray/tune/trainable/function_trainable.py", line 336, in entrypoint
    return self._trainable_func(
  File "/home/vscode/.cache/pypoetry/virtualenvs/deep-learning-G3c9zDRR-py3.9/lib/python3.9/site-packages/ray/tune/trainable/function_trainable.py", line 653, in _trainable_func
    output = fn()
  File "/workspaces/MLopdracht/hypertune.py", line 28, in train
    with FileLock(data_dir / ".lock"):
  File "/home/vscode/.cache/pypoetry/virtualenvs/deep-learning-G3c9zDRR-py3.9/lib/python3.9/site-packages/filelock/_api.py", line 260, in __enter__
    self.acquire()
  File "/home/vscode/.cache/pypoetry/virtualenvs/deep-learning-G3c9zDRR-py3.9/lib/python3.9/site-packages/filelock/_api.py", line 217, in acquire
    self._acquire()
  File "/home/vscode/.cache/pypoetry/virtualenvs/deep-learning-G3c9zDRR-py3.9/lib/python3.9/site-packages/filelock/_unix.py", line 36, in _acquire
    fd = os.open(self.lock_file, open_flags, self._context.mode)
NotADirectoryError: [Errno 20] Not a directory: '/workspaces/MLopdracht/data/raw/ArabicTrain.txt/.lock'
